Workbook

Sheet Envio
A1: Fonte | C1: Site | D1: E-mail | E1: Telefone | F1: Contato | G1: Ligação
A2: área | C2: https://www.spellclimatizacao.com.br/ | D2: spell@spellclimatizacao.com.br | E2: +55 (11) 2653-0291 | 2651-3297 | F2: 45425 | G2: Juliana, disse que recebeu e vai encaminhar para o departamento técnico | H2: 45439 | I2: Falei com Eloiza, ficou de conversar com o responsável e pedir um retorno.
A3: Google | C3: https://heronarcondicionado.com.br/?gad_source=1&gclid=CjwKCAjw9IayBhBJEiwAVuc3fhlMmtNIQm_iskoJ6qyeGto1D0fC7cQa4I7hv9MyUmKxzGkvOLsLoxoC41oQAvD_BwE | D3: atendimento@herontecnologiatermica.com.br | E3: (11) 4211-1124 | F3: 45425 | G3: Rodrigo, vai analisar.
A4: área | B4: ok | C4: http://climaplan.com.br/contato.php | D4: contato@climaplan.com.br | E4: 55 (11) 2914-3667 - 55 (11) 2068-9351 | F4: 45425 | G4: Selma, pediu para mandar no comercial
A5: Google | C5: https://refrisat.com.br/lp/climatizacao/?utm_source=google_ads&utm_campaign=%5BLeads%5D+Climatiza%C3%A7%C3%A3o+Brasil&utmAc=9143885993&gad_source=1&gclid=CjwKCAjw9IayBhBJEiwAVuc3fnZAPcDhdiIbSXESTE7Bi5jyBnmIVHIPFgYzmed3NB1RkpNnNjVlRxoCExsQAvD_BwE | D5: refrisat@refrisat.com.br | E5: 55 (11) 2423-5900 | F5: 45425 | G5: Cristiane, pediu para mandar no e-mail dela: cristiane.silva@refrisat.com.br
A6: área | C6: https://www.akmx.com.br/contato | D6: paulo.sanches@akmx.com.br | E6: (11) 4000.1845 | F6: 45426 | H6: 45439 | I6: Novamento telefone cai na Ura, deixei recado.
C7: http://www.maxfrio.com.br/index_b.asp | E7: (11) 3044-5453
C8: maxfrioatacado.com | D8: contato@maxfrioatacado.com | E8: (18) 3281-0985 | F8: 45425
A9: área | B9: ok | C9: MaxFrio Solution | D9: antonio.moreira@frileste.com.br | E9: (11) 98992-5184 | F9: 45397 | H9: 45439 | I9: Antonio, pediu para mandar no e-mail dele
C10: Projetos de climatização
B11: ok | C11: https://kamusengenharia.com.br/ | D11: projetos@kamusengenharia.com.br | E11: (11) 97886-8588 | F11: 45427 | G11: Respondeu que tem interesse | H11: 45439 | I11: Larisa, disse que combinou com o departamento dela de receber até hoje. Ficou de responder
C12: https://www.l21engenharia.com.br/ | D12: l21@l21engenharia.com.br | E12: (11) 94485-4690 | F12: 45427 | H12: 45439 | I12: Pediu para reencaminhar, Pedi um retorno até o final do dia.

Sheet Processo_xxxx-yy
A1: Objeto | I1: Declínio | J1: =COUNTIF(B:B,I1) -> 0
D2: TOTAL DE DIAS | I2: Solicitou Visita | J2: =COUNTIF(B:B,I2) -> 0
D3: {=MAX(E7:E16-D7:D16)} -> 0 | I3: Aguardando Retorno | J3: =COUNTIF(B:B,I3) -> 0
C4: Data atual/data finalização do processo | D4: =TODAY() -> 45895 | E4: (Preencher quando processo for finalizado) | I4: Resposta Aceita | J4: =COUNTIF(B:B,I4) -> 0
I5: Proposta Desconsiderada
A6: ORIGEM | B6: STATUS | C6: EMPRESA | D6: ENVIO E-MAIL | E6: RECEBIMENTO PROPOSTA | F6: E-MAIL | G6: RESP. EMPRESA | H6: TELEFONE | I6: OBS. | J6: DIAS/ FORNEC.

Sheet Propostas
B1: Mês atual
B2: Jul/25
F3: I0 original
A4: I0 original | B4: ITEM | C4: Unidade | D4: Valor adotado na data do I0 atual | E4: Adotada | F4: Média adotada | G4: Média Saneada | H4: Menor Valor | I4: Média Aritmética | J4: Mediana | K4: Empresa 1 | L4: Empresa 2 | M4: Empresa 3 | N4: Empresa 4 | O4: Empresa 5 | P4: Empresa 6 | Q4: Tempo passado entre os períodos | R4: Mês anterior ao inicial | S4: Índice do mês anterior ao inicial | T4: Índice atual | U4: Justificativa do preço adotado
D6: =_xlfn.IFS(AND(Q6>6,Q6<=36),E6*T6/S6,Q6<=6,E6,Q6=" "," ",Q6>36,"ERRO") | E6: =IF(COUNT(K6:P6)<2,I6,G6) -> #DIV/0! | F6: =IF(COUNT(K6:P6)<3*AND(E6=I6),$I$4,IF(E6=G6,$G$4,IF(E6=H6,$H$4,IF(E6=J6,$J$4,"Outro")))) -> #DIV/0! | G6: =AVERAGEIFS(K6:P6,K6:P6,"<="&(AVERAGE(K6:P6)+_xlfn.STDEV.S(K6:P6)),K6:P6,">="&(AVERAGE(K6:P6)-_xlfn.STDEV.S(K6:P6))) -> #DIV/0! | H6: =SMALL(K6:P6,1) -> #NUM! | I6: =AVERAGE(K6:P6) -> #DIV/0! | J6: =MEDIAN(K6:P6) -> #NUM! | Q6: =IF(ISBLANK(A6)," ",ROUND(($B$2-A6)/30.44,0)) | R6: =EDATE(A6,-1) -> #NUM! | S6: =VLOOKUP(R6,IPCA!$D:$E,2,FALSE) -> #NUM! | T6: =VLOOKUP($B$2,IPCA!$C:$E,3,FALSE) -> 7331.98
D8: =_xlfn.IFS(AND(Q8>6,Q8<=36),E8*T8/S8,Q8<=6,E8,Q8=" "," ",Q8>36,"ERRO") | E8: =IF(COUNT(K8:P8)<2,I8,G8) -> #DIV/0! | F8: =IF(COUNT(K8:P8)<3*AND(E8=I8),$I$4,IF(E8=G8,$G$4,IF(E8=H8,$H$4,IF(E8=J8,$J$4,"Outro")))) -> #DIV/0! | G8: =AVERAGEIFS(K8:P8,K8:P8,"<="&(AVERAGE(K8:P8)+_xlfn.STDEV.S(K8:P8)),K8:P8,">="&(AVERAGE(K8:P8)-_xlfn.STDEV.S(K8:P8))) -> #DIV/0! | H8: =SMALL(K8:P8,1) -> #NUM! | I8: =AVERAGE(K8:P8) -> #DIV/0! | J8: =MEDIAN(K8:P8) -> #NUM! | Q8: =IF(ISBLANK(A8)," ",ROUND(($B$2-A8)/30.44,0)) | R8: =EDATE(A8,-1) -> #NUM! | S8: =VLOOKUP(R8,IPCA!$D:$E,2,FALSE) -> #NUM! | T8: =VLOOKUP($B$2,IPCA!$C:$E,3,FALSE) -> 7331.98
D10: =_xlfn.IFS(AND(Q10>6,Q10<=36),E10*T10/S10,Q10<=6,E10,Q10=" "," ",Q10>36,"ERRO") | E10: =IF(COUNT(K10:P10)<2,I10,G10) -> #DIV/0! | F10: =IF(COUNT(K10:P10)<3*AND(E10=I10),$I$4,IF(E10=G10,$G$4,IF(E10=H10,$H$4,IF(E10=J10,$J$4,"Outro")))) -> #DIV/0! | G10: =AVERAGEIFS(K10:P10,K10:P10,"<="&(AVERAGE(K10:P10)+_xlfn.STDEV.S(K10:P10)),K10:P10,">="&(AVERAGE(K10:P10)-_xlfn.STDEV.S(K10:P10))) -> #DIV/0! | H10: =SMALL(K10:P10,1) -> #NUM! | I10: =AVERAGE(K10:P10) -> #DIV/0! | J10: =MEDIAN(K10:P10) -> #NUM! | Q10: =IF(ISBLANK(A10)," ",ROUND(($B$2-A10)/30.44,0)) | R10: =EDATE(A10,-1) -> #NUM! | S10: =VLOOKUP(R10,IPCA!$D:$E,2,FALSE) -> #NUM! | T10: =VLOOKUP($B$2,IPCA!$C:$E,3,FALSE) -> 7331.98
D12: =_xlfn.IFS(AND(Q12>6,Q12<=36),E12*T12/S12,Q12<=6,E12,Q12=" "," ",Q12>36,"ERRO") | E12: =IF(COUNT(K12:P12)<2,I12,G12) -> #DIV/0! | F12: =IF(COUNT(K12:P12)<3*AND(E12=I12),$I$4,IF(E12=G12,$G$4,IF(E12=H12,$H$4,IF(E12=J12,$J$4,"Outro")))) -> #DIV/0! | G12: =AVERAGEIFS(K12:P12,K12:P12,"<="&(AVERAGE(K12:P12)+_xlfn.STDEV.S(K12:P12)),K12:P12,">="&(AVERAGE(K12:P12)-_xlfn.STDEV.S(K12:P12))) -> #DIV/0! | H12: =SMALL(K12:P12,1) -> #NUM! | I12: =AVERAGE(K12:P12) -> #DIV/0! | J12: =MEDIAN(K12:P12) -> #NUM! | Q12: =IF(ISBLANK(A12)," ",ROUND(($B$2-A12)/30.44,0)) | R12: =EDATE(A12,-1) -> #NUM! | S12: =VLOOKUP(R12,IPCA!$D:$E,2,FALSE) -> #NUM! | T12: =VLOOKUP($B$2,IPCA!$C:$E,3,FALSE) -> 7331.98
D14: =_xlfn.IFS(AND(Q14>6,Q14<=36),E14*T14/S14,Q14<=6,E14,Q14=" "," ",Q14>36,"ERRO") | E14: =IF(COUNT(K14:P14)<2,I14,G14) -> #DIV/0! | F14: =IF(COUNT(K14:P14)<3*AND(E14=I14),$I$4,IF(E14=G14,$G$4,IF(E14=H14,$H$4,IF(E14=J14,$J$4,"Outro")))) -> #DIV/0! | G14: =AVERAGEIFS(K14:P14,K14:P14,"<="&(AVERAGE(K14:P14)+_xlfn.STDEV.S(K14:P14)),K14:P14,">="&(AVERAGE(K14:P14)-_xlfn.STDEV.S(K14:P14))) -> #DIV/0! | H14: =SMALL(K14:P14,1) -> #NUM! | I14: =AVERAGE(K14:P14) -> #DIV/0! | J14: =MEDIAN(K14:P14) -> #NUM! | Q14: =IF(ISBLANK(A14)," ",ROUND(($B$2-A14)/30.44,0)) | R14: =EDATE(A14,-1) -> #NUM! | S14: =VLOOKUP(R14,IPCA!$D:$E,2,FALSE) -> #NUM! | T14: =VLOOKUP($B$2,IPCA!$C:$E,3,FALSE) -> 7331.98
D16: =_xlfn.IFS(AND(Q16>6,Q16<=36),E16*T16/S16,Q16<=6,E16,Q16=" "," ",Q16>36,"ERRO") | E16: =IF(COUNT(K16:P16)<2,I16,G16) -> #DIV/0! | F16: =IF(COUNT(K16:P16)<3*AND(E16=I16),$I$4,IF(E16=G16,$G$4,IF(E16=H16,$H$4,IF(E16=J16,$J$4,"Outro")))) -> #DIV/0! | G16: =AVERAGEIFS(K16:P16,K16:P16,"<="&(AVERAGE(K16:P16)+_xlfn.STDEV.S(K16:P16)),K16:P16,">="&(AVERAGE(K16:P16)-_xlfn.STDEV.S(K16:P16))) -> #DIV/0! | H16: =SMALL(K16:P16,1) -> #NUM! | I16: =AVERAGE(K16:P16) -> #DIV/0! | J16: =MEDIAN(K16:P16) -> #NUM! | Q16: =IF(ISBLANK(A16)," ",ROUND(($B$2-A16)/30.44,0)) | R16: =EDATE(A16,-1) -> #NUM! | S16: =VLOOKUP(R16,IPCA!$D:$E,2,FALSE) -> #NUM! | T16: =VLOOKUP($B$2,IPCA!$C:$E,3,FALSE) -> 7331.98
D18: =_xlfn.IFS(AND(Q18>6,Q18<=36),E18*T18/S18,Q18<=6,E18,Q18=" "," ",Q18>36,"ERRO") | E18: =IF(COUNT(K18:P18)<2,I18,G18) -> #DIV/0! | F18: =IF(COUNT(K18:P18)<3*AND(E18=I18),$I$4,IF(E18=G18,$G$4,IF(E18=H18,$H$4,IF(E18=J18,$J$4,"Outro")))) -> #DIV/0! | G18: =AVERAGEIFS(K18:P18,K18:P18,"<="&(AVERAGE(K18:P18)+_xlfn.STDEV.S(K18:P18)),K18:P18,">="&(AVERAGE(K18:P18)-_xlfn.STDEV.S(K18:P18))) -> #DIV/0! | H18: =SMALL(K18:P18,1) -> #NUM! | I18: =AVERAGE(K18:P18) -> #DIV/0! | J18: =MEDIAN(K18:P18) -> #NUM! | Q18: =IF(ISBLANK(A18)," ",ROUND(($B$2-A18)/30.44,0)) | R18: =EDATE(A18,-1) -> #NUM! | S18: =VLOOKUP(R18,IPCA!$D:$E,2,FALSE) -> #NUM! | T18: =VLOOKUP($B$2,IPCA!$C:$E,3,FALSE) -> 7331.98
D20: =_xlfn.IFS(AND(Q20>6,Q20<=36),E20*T20/S20,Q20<=6,E20,Q20=" "," ",Q20>36,"ERRO") | E20: =IF(COUNT(K20:P20)<2,I20,G20) -> #DIV/0! | F20: =IF(COUNT(K20:P20)<3*AND(E20=I20),$I$4,IF(E20=G20,$G$4,IF(E20=H20,$H$4,IF(E20=J20,$J$4,"Outro")))) -> #DIV/0! | G20: =AVERAGEIFS(K20:P20,K20:P20,"<="&(AVERAGE(K20:P20)+_xlfn.STDEV.S(K20:P20)),K20:P20,">="&(AVERAGE(K20:P20)-_xlfn.STDEV.S(K20:P20))) -> #DIV/0! | H20: =SMALL(K20:P20,1) -> #NUM! | I20: =AVERAGE(K20:P20) -> #DIV/0! | J20: =MEDIAN(K20:P20) -> #NUM! | Q20: =IF(ISBLANK(A20)," ",ROUND(($B$2-A20)/30.44,0)) | R20: =EDATE(A20,-1) -> #NUM! | S20: =VLOOKUP(R20,IPCA!$D:$E,2,FALSE) -> #NUM! | T20: =VLOOKUP($B$2,IPCA!$C:$E,3,FALSE) -> 7331.98
D22: =_xlfn.IFS(AND(Q22>6,Q22<=36),E22*T22/S22,Q22<=6,E22,Q22=" "," ",Q22>36,"ERRO") | E22: =IF(COUNT(K22:P22)<2,I22,G22) -> #DIV/0! | F22: =IF(COUNT(K22:P22)<3*AND(E22=I22),$I$4,IF(E22=G22,$G$4,IF(E22=H22,$H$4,IF(E22=J22,$J$4,"Outro")))) -> #DIV/0! | G22: =AVERAGEIFS(K22:P22,K22:P22,"<="&(AVERAGE(K22:P22)+_xlfn.STDEV.S(K22:P22)),K22:P22,">="&(AVERAGE(K22:P22)-_xlfn.STDEV.S(K22:P22))) -> #DIV/0! | H22: =SMALL(K22:P22,1) -> #NUM! | I22: =AVERAGE(K22:P22) -> #DIV/0! | J22: =MEDIAN(K22:P22) -> #NUM! | Q22: =IF(ISBLANK(A22)," ",ROUND(($B$2-A22)/30.44,0)) | R22: =EDATE(A22,-1) -> #NUM! | S22: =VLOOKUP(R22,IPCA!$D:$E,2,FALSE) -> #NUM! | T22: =VLOOKUP($B$2,IPCA!$C:$E,3,FALSE) -> 7331.98
D24: =_xlfn.IFS(AND(Q24>6,Q24<=36),E24*T24/S24,Q24<=6,E24,Q24=" "," ",Q24>36,"ERRO") | E24: =IF(COUNT(K24:P24)<2,I24,G24) -> #DIV/0! | F24: =IF(COUNT(K24:P24)<3*AND(E24=I24),$I$4,IF(E24=G24,$G$4,IF(E24=H24,$H$4,IF(E24=J24,$J$4,"Outro")))) -> #DIV/0! | G24: =AVERAGEIFS(K24:P24,K24:P24,"<="&(AVERAGE(K24:P24)+_xlfn.STDEV.S(K24:P24)),K24:P24,">="&(AVERAGE(K24:P24)-_xlfn.STDEV.S(K24:P24))) -> #DIV/0! | H24: =SMALL(K24:P24,1) -> #NUM! | I24: =AVERAGE(K24:P24) -> #DIV/0! | J24: =MEDIAN(K24:P24) -> #NUM! | Q24: =IF(ISBLANK(A24)," ",ROUND(($B$2-A24)/30.44,0)) | R24: =EDATE(A24,-1) -> #NUM! | S24: =VLOOKUP(R24,IPCA!$D:$E,2,FALSE) -> #NUM! | T24: =VLOOKUP($B$2,IPCA!$C:$E,3,FALSE) -> 7331.98
D26: =_xlfn.IFS(AND(Q26>6,Q26<=36),E26*T26/S26,Q26<=6,E26,Q26=" "," ",Q26>36,"ERRO") | E26: =IF(COUNT(K26:P26)<2,I26,G26) -> #DIV/0! | F26: =IF(COUNT(K26:P26)<3*AND(E26=I26),$I$4,IF(E26=G26,$G$4,IF(E26=H26,$H$4,IF(E26=J26,$J$4,"Outro")))) -> #DIV/0! | G26: =AVERAGEIFS(K26:P26,K26:P26,"<="&(AVERAGE(K26:P26)+_xlfn.STDEV.S(K26:P26)),K26:P26,">="&(AVERAGE(K26:P26)-_xlfn.STDEV.S(K26:P26))) -> #DIV/0! | H26: =SMALL(K26:P26,1) -> #NUM! | I26: =AVERAGE(K26:P26) -> #DIV/0! | J26: =MEDIAN(K26:P26) -> #NUM! | Q26: =IF(ISBLANK(A26)," ",ROUND(($B$2-A26)/30.44,0)) | R26: =EDATE(A26,-1) -> #NUM! | S26: =VLOOKUP(R26,IPCA!$D:$E,2,FALSE) -> #NUM! | T26: =VLOOKUP($B$2,IPCA!$C:$E,3,FALSE) -> 7331.98
D28: =_xlfn.IFS(AND(Q28>6,Q28<=36),E28*T28/S28,Q28<=6,E28,Q28=" "," ",Q28>36,"ERRO") | E28: =IF(COUNT(K28:P28)<2,I28,G28) -> #DIV/0! | F28: =IF(COUNT(K28:P28)<3*AND(E28=I28),$I$4,IF(E28=G28,$G$4,IF(E28=H28,$H$4,IF(E28=J28,$J$4,"Outro")))) -> #DIV/0! | G28: =AVERAGEIFS(K28:P28,K28:P28,"<="&(AVERAGE(K28:P28)+_xlfn.STDEV.S(K28:P28)),K28:P28,">="&(AVERAGE(K28:P28)-_xlfn.STDEV.S(K28:P28))) -> #DIV/0! | H28: =SMALL(K28:P28,1) -> #NUM! | I28: =AVERAGE(K28:P28) -> #DIV/0! | J28: =MEDIAN(K28:P28) -> #NUM! | Q28: =IF(ISBLANK(A28)," ",ROUND(($B$2-A28)/30.44,0)) | R28: =EDATE(A28,-1) -> #NUM! | S28: =VLOOKUP(R28,IPCA!$D:$E,2,FALSE) -> #NUM! | T28: =VLOOKUP($B$2,IPCA!$C:$E,3,FALSE) -> 7331.98
... D88: =_xlfn.IFS(AND(Q88>6,Q88<=36),E88*T88/S88,Q88<=6,E88,Q88=" "," ",Q88>36,"ERRO") | E88: =IF(COUNT(K88:P88)<2,I88,G88) -> #DIV/0! | F88: =IF(COUNT(K88:P88)<3*AND(E88=I88),$I$4,IF(E88=G88,$G$4,IF(E88=H88,$H$4,IF(E88=J88,$J$4,"Outro")))) -> #DIV/0! | G88: =AVERAGEIFS(K88:P88,K88:P88,"<="&(AVERAGE(K88:P88)+_xlfn.STDEV.S(K88:P88)),K88:P88,">="&(AVERAGE(K88:P88)-_xlfn.STDEV.S(K88:P88))) -> #DIV/0! | H88: =SMALL(K88:P88,1) -> #NUM! | I88: =AVERAGE(K88:P88) -> #DIV/0! | J88: =MEDIAN(K88:P88) -> #NUM! | Q88: =IF(ISBLANK(A88)," ",ROUND(($B$2-A88)/30.44,0)) | R88: =EDATE(A88,-1) -> #NUM! | S88: =VLOOKUP(R88,IPCA!$D:$E,2,FALSE) -> #NUM! | T88: =VLOOKUP($B$2,IPCA!$C:$E,3,FALSE) -> 7331.98

Sheet Resumo
B1: OBJETO | C1: UNIDADE | D1: QUANTIDADE | E1: VALOR ADOTADO | F1: VALOR TOTAL | G1: Itens medidos
B2: =Propostas!B6 -> 0 | C2: =Propostas!C6 -> 0 | E2: =Propostas!D6 | F2: =D2*E2 -> #VALUE!
B3: =Propostas!B8 -> 0 | C3: =Propostas!C8 -> 0 | E3: =Propostas!D8 | F3: =D3*E3 -> #VALUE!
B4: =Propostas!B10 -> 0 | C4: =Propostas!C10 -> 0 | E4: =Propostas!D10 | F4: =D4*E4 -> #VALUE!
B5: =Propostas!B12 -> 0 | C5: =Propostas!C12 -> 0 | E5: =Propostas!D12 | F5: =D5*E5 -> #VALUE!
B6: =Propostas!B14 -> 0 | C6: =Propostas!C14 -> 0 | E6: =Propostas!D14 | F6: =D6*E6 -> #VALUE!
B7: =Propostas!B16 -> 0 | C7: =Propostas!C16 -> 0 | E7: =Propostas!D16 | F7: =D7*E7 -> #VALUE!
B8: =Propostas!B18 -> 0 | C8: =Propostas!C18 -> 0 | E8: =Propostas!D18 | F8: =D8*E8 -> #VALUE!
B9: =Propostas!B20 -> 0 | C9: =Propostas!C20 -> 0 | E9: =Propostas!D20 | F9: =D9*E9 -> #VALUE!
B10: =Propostas!B22 -> 0 | C10: =Propostas!C22 -> 0 | E10: =Propostas!D22 | F10: =D10*E10 -> #VALUE!
B11: =Propostas!B24 -> 0 | C11: =Propostas!C24 -> 0 | E11: =Propostas!D24 | F11: =D11*E11 -> #VALUE!
B12: =Propostas!B26 -> 0 | C12: =Propostas!C26 -> 0 | E12: =Propostas!D26 | F12: =D12*E12 -> #VALUE!
B13: =Propostas!B28 -> 0 | C13: =Propostas!C28 -> 0 | E13: =Propostas!D28 | F13: =D13*E13 -> #VALUE!
B14: =Propostas!B30 -> 0 | C14: =Propostas!C30 -> 0 | E14: =Propostas!D30 | F14: =D14*E14 -> #VALUE!
B15: =Propostas!B32 -> 0 | C15: =Propostas!C32 -> 0 | E15: =Propostas!D32 | F15: =D15*E15 -> #VALUE!
B16: =Propostas!B34 -> 0 | C16: =Propostas!C34 -> 0 | E16: =Propostas!D34 | F16: =D16*E16 -> #VALUE!
B17: =Propostas!B36 -> 0 | C17: =Propostas!C36 -> 0 | E17: =Propostas!D36 | F17: =D17*E17 -> #VALUE!
B18: =Propostas!B38 -> 0 | C18: =Propostas!C38 -> 0 | E18: =Propostas!D38 | F18: =D18*E18 -> #VALUE!
B19: =Propostas!B40 -> 0 | C19: =Propostas!C40 -> 0 | E19: =Propostas!D40 | F19: =D19*E19 -> #VALUE!
B20: =Propostas!B42 -> 0 | C20: =Propostas!C42 -> 0 | E20: =Propostas!D42 | F20: =D20*E20 -> #VALUE!
B21: =Propostas!B44 -> 0 | C21: =Propostas!C44 -> 0 | E21: =Propostas!D44 | F21: =D21*E21 -> #VALUE!
B22: =Propostas!B46 -> 0 | C22: =Propostas!C46 -> 0 | E22: =Propostas!D46 | F22: =D22*E22 -> #VALUE!
B23: =Propostas!B48 -> 0 | C23: =Propostas!C48 -> 0 | E23: =Propostas!D48 | F23: =D23*E23 -> #VALUE!
B24: =Propostas!B50 -> 0 | C24: =Propostas!C50 -> 0 | E24: =Propostas!D50 | F24: =D24*E24 -> #VALUE!
B25: =Propostas!B52 -> 0 | C25: =Propostas!C52 -> 0 | E25: =Propostas!D52 | F25: =D25*E25 -> #VALUE!
B27: JUSTIFICATIVA: | F27: =SUM(F2:F26) -> #VALUE! | G27: =SUM(G2:G26) -> 0
B28: 1) Adotado valor da média saneada conforme Procedimento EPC... 2) Adotado menor preço devido... 3) Adotado preço do fornecedor X devido...

Sheet IPCA
B1: Índices | C1: Data em texto | D1: Data | E1: Número | F1: OBS | G1: Fonte: https://sidra.ibge.gov.br/tabela/6691
B2: IPCA | C2: =TEXT(D2,"mmm/aa") -> jul/25 | D2: 45839 | E2: 7331.98
B3: IPCA | C3: =TEXT(D3,"mmm/aa") -> jun/25 | D3: 45809 | E3: 7312.97
B4: IPCA | C4: =TEXT(D4,"mmm/aa") -> mai/25 | D4: 45778 | E4: 7295.46
B5: IPCA | C5: =TEXT(D5,"mmm/aa") -> abr/25 | D5: 45748 | E5: 7276.54
B6: IPCA | C6: =TEXT(D6,"mmm/aa") -> mar/25 | D6: 45717 | E6: 7245.38
B7: IPCA | C7: =TEXT(D7,"mmm/aa") -> fev/25 | D7: 45689 | E7: 7205.03 | G7: =TRIM(A7)
B8: IPCA | C8: =TEXT(D8,"mmm/aa") -> jan/25 | D8: 45658 | E8: 7111.86
B9: IPCA | C9: =TEXT(D9,"mmm/aa") -> dez/24 | D9: 45627 | E9: 7100.5
B10: IPCA | C10: =TEXT(D10,"mmm/aa") -> nov/24 | D10: 45597 | E10: 7063.77
B11: IPCA | C11: =TEXT(D11,"mmm/aa") -> out/24 | D11: 45566 | E11: 7036.33
B12: IPCA | C12: =TEXT(D12,"mmm/aa") -> set/24 | D12: 45536 | E12: 6997.15
B13: IPCA | C13: =TEXT(D13,"mmm/aa") -> ago/24 | D13: 45505 | E13: 6966.5
B14: IPCA | C14: =TEXT(D14,"mmm/aa") -> jul/24 | D14: 45474 | E14: 6967.89
B15: IPCA | C15: =TEXT(D15,"mmm/aa") -> jun/24 | D15: 45444 | E15: 6941.51
B16: IPCA | C16: =TEXT(D16,"mmm/aa") -> mai/24 | D16: 45413 | E16: 6926.96
B17: IPCA | C17: =TEXT(D17,"mmm/aa") -> abr/24 | D17: 45383 | E17: 6895.24
B18: IPCA | C18: =TEXT(D18,"mmm/aa") -> mar/24 | D18: 45352 | E18: 6869.14
B19: IPCA | C19: =TEXT(D19,"mmm/aa") -> fev/24 | D19: 45323 | E19: 6858.17
... B47: IPCA | C47: =TEXT(D47,"mmm/aa") -> out/21 | D47: 44470 | E47: 6018.51
D238: 44470
D239: 44440
D240: 44409 | E240: 6147.087
D241: 44378 | E241: 6122.2862
D242: 44348 | E242: 6097.4854
D243: 44317 | E243: 6072.6847
D244: 44287 | E244: 6047.8839
D245: 44256 | E245: 6023.0831
D246: 44228 | E246: 5998.2824
D247: 44197 | E247: 5973.4816
D248: 44166 | E248: 5948.6808
D249: 44136 | E249: 5923.88
D250: 44105 | E250: 5899.0793
D251: 44075 | E251: 5874.2785
... D276: 43313 | E276: 5254.2592
D468: 43282
D469: 43252
D470: 43221 | E470: 5229.4585
D471: 43191 | E471: 5204.6577
D472: 43160 | E472: 5179.8569
...

Sheet Cronograma Fisico Financeiro
A1: CODIGO | B1: DESCRIÇÃO DOS SERVIÇOS | C1: VALOR DO ITEM + BDI | D1: MÊS 1 | E1: MÊS 2 | F1: MÊS 3 | G1: MÊS 4
A3: 01 | B3: "AS BUIT" DOS PRÉDIOS I,II,III EM BIM | D3: 50% | E3: 50%
A4: 02 | B4: PROJETOS DE CLIMATIZAÇÃO | D4: 25% | E4: 25% | F4: 25% | G4: 25%
A5: 03 | B5: PROJETOS COMPLEMENTARES | D5: 25% | E5: 25% | F5: 25% | G5: 25%
